2022-05-19 16:20:44,481:ERROR:connection to server at "192.168.253.130", port 5432 failed: Connection timed out (0x0000274C/10060)
	Is the server running on that host and accepting TCP/IP connections?

2022-05-19 16:41:02,625:INFO:connection to server at "192.168.253.130", port 5432 failed: Connection timed out (0x0000274C/10060)
	Is the server running on that host and accepting TCP/IP connections?

2022-05-19 16:43:19,071:INFO:connection to server at "192.168.253.130", port 5432 failed: Connection timed out (0x0000274C/10060)
	Is the server running on that host and accepting TCP/IP connections?

2022-05-19 16:43:19,071:ERROR:connection to server at "192.168.253.130", port 5432 failed: Connection timed out (0x0000274C/10060)
	Is the server running on that host and accepting TCP/IP connections?

2022-05-20 08:35:46,017:ERROR:connection to server at "localhost" (::1), port 5432 failed: Connection refused (0x0000274D/10061)
	Is the server running on that host and accepting TCP/IP connections?
connection to server at "localhost" (127.0.0.1), port 5432 failed: Connection refused (0x0000274D/10061)
	Is the server running on that host and accepting TCP/IP connections?

2022-05-20 08:36:14,004:INFO:connected
2022-05-20 08:59:22,956:INFO:connected
2022-07-18 15:51:41,014:INFO:b'[{"ID_CMD": 30, "Shiftnum": 1, "DateTime": "2022-07-18 17:14:53"}, {"ID_CMD": 30, "Shiftnum": 1, "DateTime": "2022-07-18 17:17:25"}, {"ID_CMD": 30, "Shiftnum": 1, "DateTime": "2022-07-18 17:19:21"}, {"ID_CMD": 30, "Shiftnum": 1, "DateTime": "2022-07-18 17:20:06"}, {"ID_CMD": 30, "Shiftnum": 1, "DateTime": "2022-07-18 17:21:45"}, {"ID_CMD": 30, "Shiftnum": 1, "DateTime": "2022-07-18 17:22:35"}, {"ID_CMD": 30, "Shiftnum": 1, "DateTime": "2022-07-18 17:24:28"}, {"ID_CMD": 30, "Shiftnum": 2, "DateTime": "20.05.2022T16:35:32"}, {"ID_CMD": 30, "ShiftNum": 2, "DateTime": "20.05.2022T16:35:32"}, {"ID_CMD": 30, "ShiftNum": 2, "DateTime": "20.05.2022T16:35:32"}, {"ID_CMD": 30, "ShiftNum": 2, "DateTime": "20.05.2022T16:35:32"}, {"ID_CMD": 30, "ShiftNum": 2, "DateTime": "20.05.2022T16:35:32"}, {"ID_CMD": 30, "ShiftNum": 2, "DateTime": "20.05.2022T16:35:32"}]' received!
2022-07-18 15:52:10,511:INFO:b'[{"ID_CMD": 30, "ShiftNum": 2, "DateTime": "20.05.2022T16:35:32"}]' received!
2022-08-09 10:04:46,613:INFO:Socket received: b'[{"ID_CMD": 30, "ShiftNum": 2, "DateTime": "20.05.2022T16:35:32"}]'
2022-08-09 10:04:46,613:INFO:Socket received: b''
2022-08-09 10:13:16,281:ERROR:Task exception was never retrieved
future: <Task finished name='Task-6' coro=<handler_client() done, defined at C:\Users\salibagi\PycharmProjects\RemoteAccess\RabbitMQ\server.py:45> exception=SyntaxError('unexpected EOF while parsing', ('<string>', 0, 0, ''))>
Traceback (most recent call last):
  File "C:\Users\salibagi\PycharmProjects\RemoteAccess\RabbitMQ\server.py", line 49, in handler_client
    response = str(eval(request)) + '\n'
  File "<string>", line 0
    
SyntaxError: unexpected EOF while parsing
2022-08-09 10:13:26,018:ERROR:Task exception was never retrieved
future: <Task finished name='Task-8' coro=<handler_client() done, defined at C:\Users\salibagi\PycharmProjects\RemoteAccess\RabbitMQ\server.py:45> exception=SyntaxError('unexpected EOF while parsing', ('<string>', 0, 0, ''))>
Traceback (most recent call last):
  File "C:\Users\salibagi\PycharmProjects\RemoteAccess\RabbitMQ\server.py", line 49, in handler_client
    response = str(eval(request)) + '\n'
  File "<string>", line 0
    
SyntaxError: unexpected EOF while parsing
2022-08-09 10:13:27,107:ERROR:Task exception was never retrieved
future: <Task finished name='Task-10' coro=<handler_client() done, defined at C:\Users\salibagi\PycharmProjects\RemoteAccess\RabbitMQ\server.py:45> exception=SyntaxError('unexpected EOF while parsing', ('<string>', 0, 0, ''))>
Traceback (most recent call last):
  File "C:\Users\salibagi\PycharmProjects\RemoteAccess\RabbitMQ\server.py", line 49, in handler_client
    response = str(eval(request)) + '\n'
  File "<string>", line 0
    
SyntaxError: unexpected EOF while parsing
2022-08-09 10:15:22,979:ERROR:Task exception was never retrieved
future: <Task finished name='Task-6' coro=<handler_client() done, defined at C:\Users\salibagi\PycharmProjects\RemoteAccess\RabbitMQ\server.py:46> exception=SyntaxError('unexpected EOF while parsing', ('<string>', 0, 0, ''))>
Traceback (most recent call last):
  File "C:\Users\salibagi\PycharmProjects\RemoteAccess\RabbitMQ\server.py", line 50, in handler_client
    response = str(eval(request)) + '\n'
  File "<string>", line 0
    
SyntaxError: unexpected EOF while parsing
2022-08-09 10:22:17,635:ERROR:Task exception was never retrieved
future: <Task finished name='Task-4' coro=<handler_client() done, defined at C:\Users\salibagi\PycharmProjects\RemoteAccess\RabbitMQ\server.py:46> exception=SyntaxError('unexpected EOF while parsing', ('<string>', 0, 0, ''))>
Traceback (most recent call last):
  File "C:\Users\salibagi\PycharmProjects\RemoteAccess\RabbitMQ\server.py", line 50, in handler_client
    response = str(eval(request)) + '\n'
  File "<string>", line 0
    
SyntaxError: unexpected EOF while parsing
2022-08-09 10:22:28,423:ERROR:Exception in callback _ProactorBasePipeTransport._call_connection_lost(None)
handle: <Handle _ProactorBasePipeTransport._call_connection_lost(None)>
Traceback (most recent call last):
  File "C:\Users\salibagi\AppData\Local\Programs\Python\Python39\lib\asyncio\runners.py", line 44, in run
    return loop.run_until_complete(main)
  File "C:\Users\salibagi\AppData\Local\Programs\Python\Python39\lib\asyncio\base_events.py", line 629, in run_until_complete
    self.run_forever()
  File "C:\Users\salibagi\AppData\Local\Programs\Python\Python39\lib\asyncio\windows_events.py", line 316, in run_forever
    super().run_forever()
  File "C:\Users\salibagi\AppData\Local\Programs\Python\Python39\lib\asyncio\base_events.py", line 596, in run_forever
    self._run_once()
  File "C:\Users\salibagi\AppData\Local\Programs\Python\Python39\lib\asyncio\base_events.py", line 1854, in _run_once
    event_list = self._selector.select(timeout)
  File "C:\Users\salibagi\AppData\Local\Programs\Python\Python39\lib\asyncio\windows_events.py", line 434, in select
    self._poll(timeout)
  File "C:\Users\salibagi\AppData\Local\Programs\Python\Python39\lib\asyncio\windows_events.py", line 783, in _poll
    status = _overlapped.GetQueuedCompletionStatus(self._iocp, ms)
KeyboardInterrupt

During handling of the above exception, another exception occurred:

Traceback (most recent call last):
  File "C:\Users\salibagi\AppData\Local\Programs\Python\Python39\lib\asyncio\events.py", line 80, in _run
    self._context.run(self._callback, *self._args)
  File "C:\Users\salibagi\AppData\Local\Programs\Python\Python39\lib\asyncio\proactor_events.py", line 162, in _call_connection_lost
    self._sock.shutdown(socket.SHUT_RDWR)
OSError: [WinError 10038] —делана попытка выполнить операцию на объекте, не €вл€ющемс€ сокетом
2022-08-09 10:22:29,948:ERROR:Task exception was never retrieved
future: <Task finished name='Task-4' coro=<handler_client() done, defined at C:\Users\salibagi\PycharmProjects\RemoteAccess\RabbitMQ\server.py:46> exception=SyntaxError('unexpected EOF while parsing', ('<string>', 0, 0, ''))>
Traceback (most recent call last):
  File "C:\Users\salibagi\PycharmProjects\RemoteAccess\RabbitMQ\server.py", line 50, in handler_client
    response = str(eval(request)) + '\n'
  File "<string>", line 0
    
SyntaxError: unexpected EOF while parsing
2022-08-09 10:27:26,066:ERROR:Exception in callback _ProactorBasePipeTransport._call_connection_lost(None)
handle: <Handle _ProactorBasePipeTransport._call_connection_lost(None)>
Traceback (most recent call last):
  File "C:\Users\salibagi\AppData\Local\Programs\Python\Python39\lib\asyncio\runners.py", line 44, in run
    return loop.run_until_complete(main)
  File "C:\Users\salibagi\AppData\Local\Programs\Python\Python39\lib\asyncio\base_events.py", line 629, in run_until_complete
    self.run_forever()
  File "C:\Users\salibagi\AppData\Local\Programs\Python\Python39\lib\asyncio\windows_events.py", line 316, in run_forever
    super().run_forever()
  File "C:\Users\salibagi\AppData\Local\Programs\Python\Python39\lib\asyncio\base_events.py", line 596, in run_forever
    self._run_once()
  File "C:\Users\salibagi\AppData\Local\Programs\Python\Python39\lib\asyncio\base_events.py", line 1854, in _run_once
    event_list = self._selector.select(timeout)
  File "C:\Users\salibagi\AppData\Local\Programs\Python\Python39\lib\asyncio\windows_events.py", line 434, in select
    self._poll(timeout)
  File "C:\Users\salibagi\AppData\Local\Programs\Python\Python39\lib\asyncio\windows_events.py", line 783, in _poll
    status = _overlapped.GetQueuedCompletionStatus(self._iocp, ms)
KeyboardInterrupt

During handling of the above exception, another exception occurred:

Traceback (most recent call last):
  File "C:\Users\salibagi\AppData\Local\Programs\Python\Python39\lib\asyncio\events.py", line 80, in _run
    self._context.run(self._callback, *self._args)
  File "C:\Users\salibagi\AppData\Local\Programs\Python\Python39\lib\asyncio\proactor_events.py", line 162, in _call_connection_lost
    self._sock.shutdown(socket.SHUT_RDWR)
OSError: [WinError 10038] —делана попытка выполнить операцию на объекте, не €вл€ющемс€ сокетом
2022-08-09 10:27:30,396:ERROR:Task exception was never retrieved
future: <Task finished name='Task-4' coro=<handler_client() done, defined at C:\Users\salibagi\PycharmProjects\RemoteAccess\RabbitMQ\server.py:48> exception=SyntaxError('unexpected EOF while parsing', ('<string>', 0, 0, ''))>
Traceback (most recent call last):
  File "C:\Users\salibagi\PycharmProjects\RemoteAccess\RabbitMQ\server.py", line 53, in handler_client
    response = str(eval(request)) + '\n'
  File "<string>", line 0
    
SyntaxError: unexpected EOF while parsing
2022-08-09 10:29:12,727:ERROR:Exception in callback _ProactorBasePipeTransport._call_connection_lost(None)
handle: <Handle _ProactorBasePipeTransport._call_connection_lost(None)>
Traceback (most recent call last):
  File "C:\Users\salibagi\AppData\Local\Programs\Python\Python39\lib\asyncio\runners.py", line 44, in run
    return loop.run_until_complete(main)
  File "C:\Users\salibagi\AppData\Local\Programs\Python\Python39\lib\asyncio\base_events.py", line 629, in run_until_complete
    self.run_forever()
  File "C:\Users\salibagi\AppData\Local\Programs\Python\Python39\lib\asyncio\windows_events.py", line 316, in run_forever
    super().run_forever()
  File "C:\Users\salibagi\AppData\Local\Programs\Python\Python39\lib\asyncio\base_events.py", line 596, in run_forever
    self._run_once()
  File "C:\Users\salibagi\AppData\Local\Programs\Python\Python39\lib\asyncio\base_events.py", line 1854, in _run_once
    event_list = self._selector.select(timeout)
  File "C:\Users\salibagi\AppData\Local\Programs\Python\Python39\lib\asyncio\windows_events.py", line 434, in select
    self._poll(timeout)
  File "C:\Users\salibagi\AppData\Local\Programs\Python\Python39\lib\asyncio\windows_events.py", line 783, in _poll
    status = _overlapped.GetQueuedCompletionStatus(self._iocp, ms)
KeyboardInterrupt

During handling of the above exception, another exception occurred:

Traceback (most recent call last):
  File "C:\Users\salibagi\AppData\Local\Programs\Python\Python39\lib\asyncio\events.py", line 80, in _run
    self._context.run(self._callback, *self._args)
  File "C:\Users\salibagi\AppData\Local\Programs\Python\Python39\lib\asyncio\proactor_events.py", line 162, in _call_connection_lost
    self._sock.shutdown(socket.SHUT_RDWR)
OSError: [WinError 10038] —делана попытка выполнить операцию на объекте, не €вл€ющемс€ сокетом
2022-08-09 10:29:14,531:ERROR:Task exception was never retrieved
future: <Task finished name='Task-4' coro=<handler_client() done, defined at C:\Users\salibagi\PycharmProjects\RemoteAccess\RabbitMQ\server.py:48> exception=SyntaxError('unexpected EOF while parsing', ('<string>', 0, 0, ''))>
Traceback (most recent call last):
  File "C:\Users\salibagi\PycharmProjects\RemoteAccess\RabbitMQ\server.py", line 53, in handler_client
    response = str(eval(request)) + '\n'
  File "<string>", line 0
    
SyntaxError: unexpected EOF while parsing
2022-08-09 10:29:31,297:ERROR:Exception in callback _ProactorBasePipeTransport._call_connection_lost(None)
handle: <Handle _ProactorBasePipeTransport._call_connection_lost(None)>
Traceback (most recent call last):
  File "C:\Users\salibagi\AppData\Local\Programs\Python\Python39\lib\asyncio\runners.py", line 44, in run
    return loop.run_until_complete(main)
  File "C:\Users\salibagi\AppData\Local\Programs\Python\Python39\lib\asyncio\base_events.py", line 629, in run_until_complete
    self.run_forever()
  File "C:\Users\salibagi\AppData\Local\Programs\Python\Python39\lib\asyncio\windows_events.py", line 316, in run_forever
    super().run_forever()
  File "C:\Users\salibagi\AppData\Local\Programs\Python\Python39\lib\asyncio\base_events.py", line 596, in run_forever
    self._run_once()
  File "C:\Users\salibagi\AppData\Local\Programs\Python\Python39\lib\asyncio\base_events.py", line 1854, in _run_once
    event_list = self._selector.select(timeout)
  File "C:\Users\salibagi\AppData\Local\Programs\Python\Python39\lib\asyncio\windows_events.py", line 434, in select
    self._poll(timeout)
  File "C:\Users\salibagi\AppData\Local\Programs\Python\Python39\lib\asyncio\windows_events.py", line 783, in _poll
    status = _overlapped.GetQueuedCompletionStatus(self._iocp, ms)
KeyboardInterrupt

During handling of the above exception, another exception occurred:

Traceback (most recent call last):
  File "C:\Users\salibagi\AppData\Local\Programs\Python\Python39\lib\asyncio\events.py", line 80, in _run
    self._context.run(self._callback, *self._args)
  File "C:\Users\salibagi\AppData\Local\Programs\Python\Python39\lib\asyncio\proactor_events.py", line 162, in _call_connection_lost
    self._sock.shutdown(socket.SHUT_RDWR)
OSError: [WinError 10038] —делана попытка выполнить операцию на объекте, не €вл€ющемс€ сокетом
2022-08-09 10:29:33,294:ERROR:Task exception was never retrieved
future: <Task finished name='Task-4' coro=<handler_client() done, defined at C:\Users\salibagi\PycharmProjects\RemoteAccess\RabbitMQ\server.py:48> exception=SyntaxError('unexpected EOF while parsing', ('<string>', 0, 0, ''))>
Traceback (most recent call last):
  File "C:\Users\salibagi\PycharmProjects\RemoteAccess\RabbitMQ\server.py", line 53, in handler_client
    response = str(eval(request))
  File "<string>", line 0
    
SyntaxError: unexpected EOF while parsing
2022-08-09 10:30:05,798:ERROR:Exception in callback _ProactorBasePipeTransport._call_connection_lost(None)
handle: <Handle _ProactorBasePipeTransport._call_connection_lost(None)>
Traceback (most recent call last):
  File "C:\Users\salibagi\AppData\Local\Programs\Python\Python39\lib\asyncio\runners.py", line 44, in run
    return loop.run_until_complete(main)
  File "C:\Users\salibagi\AppData\Local\Programs\Python\Python39\lib\asyncio\base_events.py", line 629, in run_until_complete
    self.run_forever()
  File "C:\Users\salibagi\AppData\Local\Programs\Python\Python39\lib\asyncio\windows_events.py", line 316, in run_forever
    super().run_forever()
  File "C:\Users\salibagi\AppData\Local\Programs\Python\Python39\lib\asyncio\base_events.py", line 596, in run_forever
    self._run_once()
  File "C:\Users\salibagi\AppData\Local\Programs\Python\Python39\lib\asyncio\base_events.py", line 1854, in _run_once
    event_list = self._selector.select(timeout)
  File "C:\Users\salibagi\AppData\Local\Programs\Python\Python39\lib\asyncio\windows_events.py", line 434, in select
    self._poll(timeout)
  File "C:\Users\salibagi\AppData\Local\Programs\Python\Python39\lib\asyncio\windows_events.py", line 783, in _poll
    status = _overlapped.GetQueuedCompletionStatus(self._iocp, ms)
KeyboardInterrupt

During handling of the above exception, another exception occurred:

Traceback (most recent call last):
  File "C:\Users\salibagi\AppData\Local\Programs\Python\Python39\lib\asyncio\events.py", line 80, in _run
    self._context.run(self._callback, *self._args)
  File "C:\Users\salibagi\AppData\Local\Programs\Python\Python39\lib\asyncio\proactor_events.py", line 162, in _call_connection_lost
    self._sock.shutdown(socket.SHUT_RDWR)
OSError: [WinError 10038] —делана попытка выполнить операцию на объекте, не €вл€ющемс€ сокетом
2022-08-10 09:34:38,968:ERROR:Couldn't decode this message !
2022-08-10 09:34:38,968:ERROR:Task exception was never retrieved
future: <Task finished name='Task-4' coro=<handler_client() done, defined at C:\Users\salibagi\PycharmProjects\RemoteAccess\RabbitMQ\server.py:45> exception=AttributeError('__aenter__')>
Traceback (most recent call last):
  File "C:\Users\salibagi\PycharmProjects\RemoteAccess\RabbitMQ\server.py", line 67, in handler_client
    async with open('data.txt', 'a') as f:
AttributeError: __aenter__
2022-08-10 09:37:24,920:ERROR:Couldn't decode this message !
2022-08-10 09:37:24,920:ERROR:Task exception was never retrieved
future: <Task finished name='Task-4' coro=<handler_client() done, defined at C:\Users\salibagi\PycharmProjects\RemoteAccess\RabbitMQ\server.py:45> exception=AttributeError('__aenter__')>
Traceback (most recent call last):
  File "C:\Users\salibagi\PycharmProjects\RemoteAccess\RabbitMQ\server.py", line 67, in handler_client
    async with open('data.txt', 'a') as f:
AttributeError: __aenter__
2022-08-10 09:37:48,689:ERROR:Couldn't decode this message !
2022-08-10 09:37:48,689:ERROR:Task exception was never retrieved
future: <Task finished name='Task-4' coro=<handler_client() done, defined at C:\Users\salibagi\PycharmProjects\RemoteAccess\RabbitMQ\server.py:45> exception=AttributeError('__aenter__')>
Traceback (most recent call last):
  File "C:\Users\salibagi\PycharmProjects\RemoteAccess\RabbitMQ\server.py", line 70, in handler_client
    async with open('data.txt', 'a') as f:
AttributeError: __aenter__
2022-08-10 09:38:24,649:ERROR:Exception in callback _ProactorBasePipeTransport._call_connection_lost(None)
handle: <Handle _ProactorBasePipeTransport._call_connection_lost(None)>
Traceback (most recent call last):
  File "C:\Users\salibagi\AppData\Local\Programs\Python\Python39\lib\asyncio\runners.py", line 44, in run
    return loop.run_until_complete(main)
  File "C:\Users\salibagi\AppData\Local\Programs\Python\Python39\lib\asyncio\base_events.py", line 629, in run_until_complete
    self.run_forever()
  File "C:\Users\salibagi\AppData\Local\Programs\Python\Python39\lib\asyncio\windows_events.py", line 316, in run_forever
    super().run_forever()
  File "C:\Users\salibagi\AppData\Local\Programs\Python\Python39\lib\asyncio\base_events.py", line 596, in run_forever
    self._run_once()
  File "C:\Users\salibagi\AppData\Local\Programs\Python\Python39\lib\asyncio\base_events.py", line 1854, in _run_once
    event_list = self._selector.select(timeout)
  File "C:\Users\salibagi\AppData\Local\Programs\Python\Python39\lib\asyncio\windows_events.py", line 434, in select
    self._poll(timeout)
  File "C:\Users\salibagi\AppData\Local\Programs\Python\Python39\lib\asyncio\windows_events.py", line 783, in _poll
    status = _overlapped.GetQueuedCompletionStatus(self._iocp, ms)
KeyboardInterrupt

During handling of the above exception, another exception occurred:

Traceback (most recent call last):
  File "C:\Users\salibagi\AppData\Local\Programs\Python\Python39\lib\asyncio\events.py", line 80, in _run
    self._context.run(self._callback, *self._args)
  File "C:\Users\salibagi\AppData\Local\Programs\Python\Python39\lib\asyncio\proactor_events.py", line 162, in _call_connection_lost
    self._sock.shutdown(socket.SHUT_RDWR)
OSError: [WinError 10038] —делана попытка выполнить операцию на объекте, не €вл€ющемс€ сокетом
2022-08-10 09:38:26,533:ERROR:Task exception was never retrieved
future: <Task finished name='Task-4' coro=<handler_client() done, defined at C:\Users\salibagi\PycharmProjects\RemoteAccess\RabbitMQ\server.py:45> exception=AttributeError('__aenter__')>
Traceback (most recent call last):
  File "C:\Users\salibagi\PycharmProjects\RemoteAccess\RabbitMQ\server.py", line 71, in handler_client
    async with open('data.txt', 'a') as f:
AttributeError: __aenter__
2022-08-10 09:38:40,545:ERROR:Task exception was never retrieved
future: <Task finished name='Task-6' coro=<handler_client() done, defined at C:\Users\salibagi\PycharmProjects\RemoteAccess\RabbitMQ\server.py:45> exception=AttributeError('__aenter__')>
Traceback (most recent call last):
  File "C:\Users\salibagi\PycharmProjects\RemoteAccess\RabbitMQ\server.py", line 71, in handler_client
    async with open('data.txt', 'a') as f:
AttributeError: __aenter__
2022-08-10 09:38:40,545:ERROR:Exception in callback _ProactorBasePipeTransport._call_connection_lost(None)
handle: <Handle _ProactorBasePipeTransport._call_connection_lost(None)>
Traceback (most recent call last):
  File "C:\Users\salibagi\AppData\Local\Programs\Python\Python39\lib\asyncio\events.py", line 80, in _run
    self._context.run(self._callback, *self._args)
  File "C:\Users\salibagi\AppData\Local\Programs\Python\Python39\lib\asyncio\proactor_events.py", line 162, in _call_connection_lost
    self._sock.shutdown(socket.SHUT_RDWR)
OSError: [WinError 10038] —делана попытка выполнить операцию на объекте, не €вл€ющемс€ сокетом
2022-08-10 09:38:45,303:ERROR:Task exception was never retrieved
future: <Task finished name='Task-4' coro=<handler_client() done, defined at C:\Users\salibagi\PycharmProjects\RemoteAccess\RabbitMQ\server.py:45> exception=AttributeError('__aenter__')>
Traceback (most recent call last):
  File "C:\Users\salibagi\PycharmProjects\RemoteAccess\RabbitMQ\server.py", line 71, in handler_client
    async with open('data.txt', 'a') as f:
AttributeError: __aenter__
2022-08-10 09:39:18,564:ERROR:Task exception was never retrieved
future: <Task finished name='Task-6' coro=<handler_client() done, defined at C:\Users\salibagi\PycharmProjects\RemoteAccess\RabbitMQ\server.py:45> exception=AttributeError('__aenter__')>
Traceback (most recent call last):
  File "C:\Users\salibagi\PycharmProjects\RemoteAccess\RabbitMQ\server.py", line 71, in handler_client
AttributeError: __aenter__
2022-08-10 09:39:18,564:ERROR:Exception in callback _ProactorBasePipeTransport._call_connection_lost(None)
handle: <Handle _ProactorBasePipeTransport._call_connection_lost(None)>
Traceback (most recent call last):
  File "C:\Users\salibagi\AppData\Local\Programs\Python\Python39\lib\asyncio\events.py", line 80, in _run
    self._context.run(self._callback, *self._args)
  File "C:\Users\salibagi\AppData\Local\Programs\Python\Python39\lib\asyncio\proactor_events.py", line 162, in _call_connection_lost
    self._sock.shutdown(socket.SHUT_RDWR)
OSError: [WinError 10038] —делана попытка выполнить операцию на объекте, не €вл€ющемс€ сокетом
2022-08-10 09:39:22,516:ERROR:Task exception was never retrieved
future: <Task finished name='Task-4' coro=<handler_client() done, defined at C:\Users\salibagi\PycharmProjects\RemoteAccess\RabbitMQ\server.py:45> exception=AttributeError('__aenter__')>
Traceback (most recent call last):
  File "C:\Users\salibagi\PycharmProjects\RemoteAccess\RabbitMQ\server.py", line 72, in handler_client
    async with open('data.txt', 'a') as f:
AttributeError: __aenter__
2022-08-10 09:39:56,365:ERROR:Exception in callback _ProactorBasePipeTransport._call_connection_lost(None)
handle: <Handle _ProactorBasePipeTransport._call_connection_lost(None)>
Traceback (most recent call last):
  File "C:\Users\salibagi\AppData\Local\Programs\Python\Python39\lib\asyncio\runners.py", line 44, in run
    return loop.run_until_complete(main)
  File "C:\Users\salibagi\AppData\Local\Programs\Python\Python39\lib\asyncio\base_events.py", line 629, in run_until_complete
    self.run_forever()
  File "C:\Users\salibagi\AppData\Local\Programs\Python\Python39\lib\asyncio\windows_events.py", line 316, in run_forever
    super().run_forever()
  File "C:\Users\salibagi\AppData\Local\Programs\Python\Python39\lib\asyncio\base_events.py", line 596, in run_forever
    self._run_once()
  File "C:\Users\salibagi\AppData\Local\Programs\Python\Python39\lib\asyncio\base_events.py", line 1854, in _run_once
    event_list = self._selector.select(timeout)
  File "C:\Users\salibagi\AppData\Local\Programs\Python\Python39\lib\asyncio\windows_events.py", line 434, in select
    self._poll(timeout)
  File "C:\Users\salibagi\AppData\Local\Programs\Python\Python39\lib\asyncio\windows_events.py", line 783, in _poll
    status = _overlapped.GetQueuedCompletionStatus(self._iocp, ms)
KeyboardInterrupt

During handling of the above exception, another exception occurred:

Traceback (most recent call last):
  File "C:\Users\salibagi\AppData\Local\Programs\Python\Python39\lib\asyncio\events.py", line 80, in _run
    self._context.run(self._callback, *self._args)
  File "C:\Users\salibagi\AppData\Local\Programs\Python\Python39\lib\asyncio\proactor_events.py", line 162, in _call_connection_lost
    self._sock.shutdown(socket.SHUT_RDWR)
OSError: [WinError 10038] —делана попытка выполнить операцию на объекте, не €вл€ющемс€ сокетом
2022-08-10 09:39:58,706:ERROR:Couldn't decode this message !
2022-08-10 09:39:58,706:ERROR:Task exception was never retrieved
future: <Task finished name='Task-4' coro=<handler_client() done, defined at C:\Users\salibagi\PycharmProjects\RemoteAccess\RabbitMQ\server.py:45> exception=AttributeError('__aenter__')>
Traceback (most recent call last):
  File "C:\Users\salibagi\PycharmProjects\RemoteAccess\RabbitMQ\server.py", line 73, in handler_client
    async with open('data.txt', 'a') as f:
AttributeError: __aenter__
2022-08-10 09:40:03,691:ERROR:Couldn't decode this message !
2022-08-10 09:40:03,691:ERROR:Task exception was never retrieved
future: <Task finished name='Task-6' coro=<handler_client() done, defined at C:\Users\salibagi\PycharmProjects\RemoteAccess\RabbitMQ\server.py:45> exception=AttributeError('__aenter__')>
Traceback (most recent call last):
  File "C:\Users\salibagi\PycharmProjects\RemoteAccess\RabbitMQ\server.py", line 73, in handler_client
    async with open('data.txt', 'a') as f:
AttributeError: __aenter__
2022-08-10 09:40:03,691:ERROR:Exception in callback _ProactorBasePipeTransport._call_connection_lost(None)
handle: <Handle _ProactorBasePipeTransport._call_connection_lost(None)>
Traceback (most recent call last):
  File "C:\Users\salibagi\AppData\Local\Programs\Python\Python39\lib\asyncio\events.py", line 80, in _run
    self._context.run(self._callback, *self._args)
  File "C:\Users\salibagi\AppData\Local\Programs\Python\Python39\lib\asyncio\proactor_events.py", line 162, in _call_connection_lost
    self._sock.shutdown(socket.SHUT_RDWR)
OSError: [WinError 10038] —делана попытка выполнить операцию на объекте, не €вл€ющемс€ сокетом
2022-08-10 09:40:24,181:ERROR:Task exception was never retrieved
future: <Task finished name='Task-4' coro=<handler_client() done, defined at C:\Users\salibagi\PycharmProjects\RemoteAccess\RabbitMQ\server.py:45> exception=AttributeError('__aenter__')>
Traceback (most recent call last):
  File "C:\Users\salibagi\PycharmProjects\RemoteAccess\RabbitMQ\server.py", line 73, in handler_client
    async with open('data.txt', 'a') as f:
AttributeError: __aenter__
2022-08-10 09:40:40,276:ERROR:Exception in callback _ProactorBasePipeTransport._call_connection_lost(None)
handle: <Handle _ProactorBasePipeTransport._call_connection_lost(None)>
Traceback (most recent call last):
  File "C:\Users\salibagi\AppData\Local\Programs\Python\Python39\lib\asyncio\runners.py", line 44, in run
    return loop.run_until_complete(main)
  File "C:\Users\salibagi\AppData\Local\Programs\Python\Python39\lib\asyncio\base_events.py", line 629, in run_until_complete
    self.run_forever()
  File "C:\Users\salibagi\AppData\Local\Programs\Python\Python39\lib\asyncio\windows_events.py", line 316, in run_forever
    super().run_forever()
  File "C:\Users\salibagi\AppData\Local\Programs\Python\Python39\lib\asyncio\base_events.py", line 596, in run_forever
    self._run_once()
  File "C:\Users\salibagi\AppData\Local\Programs\Python\Python39\lib\asyncio\base_events.py", line 1854, in _run_once
    event_list = self._selector.select(timeout)
  File "C:\Users\salibagi\AppData\Local\Programs\Python\Python39\lib\asyncio\windows_events.py", line 434, in select
    self._poll(timeout)
  File "C:\Users\salibagi\AppData\Local\Programs\Python\Python39\lib\asyncio\windows_events.py", line 783, in _poll
    status = _overlapped.GetQueuedCompletionStatus(self._iocp, ms)
KeyboardInterrupt

During handling of the above exception, another exception occurred:

Traceback (most recent call last):
  File "C:\Users\salibagi\AppData\Local\Programs\Python\Python39\lib\asyncio\events.py", line 80, in _run
    self._context.run(self._callback, *self._args)
  File "C:\Users\salibagi\AppData\Local\Programs\Python\Python39\lib\asyncio\proactor_events.py", line 162, in _call_connection_lost
    self._sock.shutdown(socket.SHUT_RDWR)
OSError: [WinError 10038] —делана попытка выполнить операцию на объекте, не €вл€ющемс€ сокетом
2022-08-10 09:40:42,448:ERROR:Task exception was never retrieved
future: <Task finished name='Task-4' coro=<handler_client() done, defined at C:\Users\salibagi\PycharmProjects\RemoteAccess\RabbitMQ\server.py:45> exception=AttributeError('__aenter__')>
Traceback (most recent call last):
  File "C:\Users\salibagi\PycharmProjects\RemoteAccess\RabbitMQ\server.py", line 74, in handler_client
    async with open('data.txt', 'a') as f:
AttributeError: __aenter__
2022-08-10 09:41:03,085:ERROR:Exception in callback _ProactorBasePipeTransport._call_connection_lost(None)
handle: <Handle _ProactorBasePipeTransport._call_connection_lost(None)>
Traceback (most recent call last):
  File "C:\Users\salibagi\AppData\Local\Programs\Python\Python39\lib\asyncio\runners.py", line 44, in run
    return loop.run_until_complete(main)
  File "C:\Users\salibagi\AppData\Local\Programs\Python\Python39\lib\asyncio\base_events.py", line 629, in run_until_complete
    self.run_forever()
  File "C:\Users\salibagi\AppData\Local\Programs\Python\Python39\lib\asyncio\windows_events.py", line 316, in run_forever
    super().run_forever()
  File "C:\Users\salibagi\AppData\Local\Programs\Python\Python39\lib\asyncio\base_events.py", line 596, in run_forever
    self._run_once()
  File "C:\Users\salibagi\AppData\Local\Programs\Python\Python39\lib\asyncio\base_events.py", line 1854, in _run_once
    event_list = self._selector.select(timeout)
  File "C:\Users\salibagi\AppData\Local\Programs\Python\Python39\lib\asyncio\windows_events.py", line 434, in select
    self._poll(timeout)
  File "C:\Users\salibagi\AppData\Local\Programs\Python\Python39\lib\asyncio\windows_events.py", line 783, in _poll
    status = _overlapped.GetQueuedCompletionStatus(self._iocp, ms)
KeyboardInterrupt

During handling of the above exception, another exception occurred:

Traceback (most recent call last):
  File "C:\Users\salibagi\AppData\Local\Programs\Python\Python39\lib\asyncio\events.py", line 80, in _run
    self._context.run(self._callback, *self._args)
  File "C:\Users\salibagi\AppData\Local\Programs\Python\Python39\lib\asyncio\proactor_events.py", line 162, in _call_connection_lost
    self._sock.shutdown(socket.SHUT_RDWR)
OSError: [WinError 10038] —делана попытка выполнить операцию на объекте, не €вл€ющемс€ сокетом
2022-08-10 09:41:04,506:ERROR:Task exception was never retrieved
future: <Task finished name='Task-4' coro=<handler_client() done, defined at C:\Users\salibagi\PycharmProjects\RemoteAccess\RabbitMQ\server.py:45> exception=AttributeError('__aenter__')>
Traceback (most recent call last):
  File "C:\Users\salibagi\PycharmProjects\RemoteAccess\RabbitMQ\server.py", line 73, in handler_client
    async with open('data.txt', 'a') as f:
AttributeError: __aenter__
2022-08-10 09:41:43,772:ERROR:Exception in callback _ProactorBasePipeTransport._call_connection_lost(None)
handle: <Handle _ProactorBasePipeTransport._call_connection_lost(None)>
Traceback (most recent call last):
  File "C:\Users\salibagi\AppData\Local\Programs\Python\Python39\lib\asyncio\runners.py", line 44, in run
    return loop.run_until_complete(main)
  File "C:\Users\salibagi\AppData\Local\Programs\Python\Python39\lib\asyncio\base_events.py", line 629, in run_until_complete
    self.run_forever()
  File "C:\Users\salibagi\AppData\Local\Programs\Python\Python39\lib\asyncio\windows_events.py", line 316, in run_forever
    super().run_forever()
  File "C:\Users\salibagi\AppData\Local\Programs\Python\Python39\lib\asyncio\base_events.py", line 596, in run_forever
    self._run_once()
  File "C:\Users\salibagi\AppData\Local\Programs\Python\Python39\lib\asyncio\base_events.py", line 1854, in _run_once
    event_list = self._selector.select(timeout)
  File "C:\Users\salibagi\AppData\Local\Programs\Python\Python39\lib\asyncio\windows_events.py", line 434, in select
    self._poll(timeout)
  File "C:\Users\salibagi\AppData\Local\Programs\Python\Python39\lib\asyncio\windows_events.py", line 783, in _poll
    status = _overlapped.GetQueuedCompletionStatus(self._iocp, ms)
KeyboardInterrupt

During handling of the above exception, another exception occurred:

Traceback (most recent call last):
  File "C:\Users\salibagi\AppData\Local\Programs\Python\Python39\lib\asyncio\events.py", line 80, in _run
    self._context.run(self._callback, *self._args)
  File "C:\Users\salibagi\AppData\Local\Programs\Python\Python39\lib\asyncio\proactor_events.py", line 162, in _call_connection_lost
    self._sock.shutdown(socket.SHUT_RDWR)
OSError: [WinError 10038] —делана попытка выполнить операцию на объекте, не €вл€ющемс€ сокетом
2022-08-10 09:41:45,512:ERROR:Task exception was never retrieved
future: <Task finished name='Task-4' coro=<handler_client() done, defined at C:\Users\salibagi\PycharmProjects\RemoteAccess\RabbitMQ\server.py:45> exception=AttributeError('__aenter__')>
Traceback (most recent call last):
  File "C:\Users\salibagi\PycharmProjects\RemoteAccess\RabbitMQ\server.py", line 68, in handler_client
    async with open('data.txt', 'a') as f:
AttributeError: __aenter__
2022-08-10 09:41:55,014:ERROR:Exception in callback _ProactorBasePipeTransport._call_connection_lost(None)
handle: <Handle _ProactorBasePipeTransport._call_connection_lost(None)>
Traceback (most recent call last):
  File "C:\Users\salibagi\AppData\Local\Programs\Python\Python39\lib\asyncio\runners.py", line 44, in run
    return loop.run_until_complete(main)
  File "C:\Users\salibagi\AppData\Local\Programs\Python\Python39\lib\asyncio\base_events.py", line 629, in run_until_complete
    self.run_forever()
  File "C:\Users\salibagi\AppData\Local\Programs\Python\Python39\lib\asyncio\windows_events.py", line 316, in run_forever
    super().run_forever()
  File "C:\Users\salibagi\AppData\Local\Programs\Python\Python39\lib\asyncio\base_events.py", line 596, in run_forever
    self._run_once()
  File "C:\Users\salibagi\AppData\Local\Programs\Python\Python39\lib\asyncio\base_events.py", line 1854, in _run_once
    event_list = self._selector.select(timeout)
  File "C:\Users\salibagi\AppData\Local\Programs\Python\Python39\lib\asyncio\windows_events.py", line 434, in select
    self._poll(timeout)
  File "C:\Users\salibagi\AppData\Local\Programs\Python\Python39\lib\asyncio\windows_events.py", line 783, in _poll
    status = _overlapped.GetQueuedCompletionStatus(self._iocp, ms)
KeyboardInterrupt

During handling of the above exception, another exception occurred:

Traceback (most recent call last):
  File "C:\Users\salibagi\AppData\Local\Programs\Python\Python39\lib\asyncio\events.py", line 80, in _run
    self._context.run(self._callback, *self._args)
  File "C:\Users\salibagi\AppData\Local\Programs\Python\Python39\lib\asyncio\proactor_events.py", line 162, in _call_connection_lost
    self._sock.shutdown(socket.SHUT_RDWR)
OSError: [WinError 10038] —делана попытка выполнить операцию на объекте, не €вл€ющемс€ сокетом
2022-08-10 09:41:56,633:ERROR:Task exception was never retrieved
future: <Task finished name='Task-4' coro=<handler_client() done, defined at C:\Users\salibagi\PycharmProjects\RemoteAccess\RabbitMQ\server.py:45> exception=TypeError('Object of type set is not JSON serializable')>
Traceback (most recent call last):
  File "C:\Users\salibagi\PycharmProjects\RemoteAccess\RabbitMQ\server.py", line 69, in handler_client
    message = json.dumps(received_message)
  File "C:\Users\salibagi\AppData\Local\Programs\Python\Python39\lib\json\__init__.py", line 231, in dumps
    return _default_encoder.encode(obj)
  File "C:\Users\salibagi\AppData\Local\Programs\Python\Python39\lib\json\encoder.py", line 199, in encode
    chunks = self.iterencode(o, _one_shot=True)
  File "C:\Users\salibagi\AppData\Local\Programs\Python\Python39\lib\json\encoder.py", line 257, in iterencode
    return _iterencode(o, 0)
  File "C:\Users\salibagi\AppData\Local\Programs\Python\Python39\lib\json\encoder.py", line 179, in default
    raise TypeError(f'Object of type {o.__class__.__name__} '
TypeError: Object of type set is not JSON serializable
2022-08-10 09:42:20,568:ERROR:Task exception was never retrieved
future: <Task finished name='Task-6' coro=<handler_client() done, defined at C:\Users\salibagi\PycharmProjects\RemoteAccess\RabbitMQ\server.py:45> exception=TypeError('Object of type set is not JSON serializable')>
Traceback (most recent call last):
  File "C:\Users\salibagi\PycharmProjects\RemoteAccess\RabbitMQ\server.py", line 69, in handler_client
    message = json.dumps(received_message)
  File "C:\Users\salibagi\AppData\Local\Programs\Python\Python39\lib\json\__init__.py", line 231, in dumps
    return _default_encoder.encode(obj)
  File "C:\Users\salibagi\AppData\Local\Programs\Python\Python39\lib\json\encoder.py", line 199, in encode
    chunks = self.iterencode(o, _one_shot=True)
  File "C:\Users\salibagi\AppData\Local\Programs\Python\Python39\lib\json\encoder.py", line 257, in iterencode
    return _iterencode(o, 0)
  File "C:\Users\salibagi\AppData\Local\Programs\Python\Python39\lib\json\encoder.py", line 179, in default
    raise TypeError(f'Object of type {o.__class__.__name__} '
TypeError: Object of type set is not JSON serializable
2022-08-10 09:42:24,421:ERROR:Task exception was never retrieved
future: <Task finished name='Task-4' coro=<handler_client() done, defined at C:\Users\salibagi\PycharmProjects\RemoteAccess\RabbitMQ\server.py:45> exception=TypeError('Object of type set is not JSON serializable')>
Traceback (most recent call last):
  File "C:\Users\salibagi\PycharmProjects\RemoteAccess\RabbitMQ\server.py", line 69, in handler_client
    message = json.dumps(received_message)
  File "C:\Users\salibagi\AppData\Local\Programs\Python\Python39\lib\json\__init__.py", line 231, in dumps
    return _default_encoder.encode(obj)
  File "C:\Users\salibagi\AppData\Local\Programs\Python\Python39\lib\json\encoder.py", line 199, in encode
    chunks = self.iterencode(o, _one_shot=True)
  File "C:\Users\salibagi\AppData\Local\Programs\Python\Python39\lib\json\encoder.py", line 257, in iterencode
    return _iterencode(o, 0)
  File "C:\Users\salibagi\AppData\Local\Programs\Python\Python39\lib\json\encoder.py", line 179, in default
    raise TypeError(f'Object of type {o.__class__.__name__} '
TypeError: Object of type set is not JSON serializable
2022-08-10 09:42:42,007:ERROR:Task exception was never retrieved
future: <Task finished name='Task-4' coro=<handler_client() done, defined at C:\Users\salibagi\PycharmProjects\RemoteAccess\RabbitMQ\server.py:45> exception=SyntaxError('unexpected EOF while parsing', ('<string>', 0, 0, ''))>
Traceback (most recent call last):
  File "C:\Users\salibagi\PycharmProjects\RemoteAccess\RabbitMQ\server.py", line 50, in handler_client
    response = str(eval(request))
  File "<string>", line 0
    
SyntaxError: unexpected EOF while parsing
2022-08-10 09:44:17,664:ERROR:Exception in callback _ProactorBasePipeTransport._call_connection_lost(None)
handle: <Handle _ProactorBasePipeTransport._call_connection_lost(None)>
Traceback (most recent call last):
  File "C:\Users\salibagi\AppData\Local\Programs\Python\Python39\lib\asyncio\runners.py", line 44, in run
    return loop.run_until_complete(main)
  File "C:\Users\salibagi\AppData\Local\Programs\Python\Python39\lib\asyncio\base_events.py", line 629, in run_until_complete
    self.run_forever()
  File "C:\Users\salibagi\AppData\Local\Programs\Python\Python39\lib\asyncio\windows_events.py", line 316, in run_forever
    super().run_forever()
  File "C:\Users\salibagi\AppData\Local\Programs\Python\Python39\lib\asyncio\base_events.py", line 596, in run_forever
    self._run_once()
  File "C:\Users\salibagi\AppData\Local\Programs\Python\Python39\lib\asyncio\base_events.py", line 1854, in _run_once
    event_list = self._selector.select(timeout)
  File "C:\Users\salibagi\AppData\Local\Programs\Python\Python39\lib\asyncio\windows_events.py", line 434, in select
    self._poll(timeout)
  File "C:\Users\salibagi\AppData\Local\Programs\Python\Python39\lib\asyncio\windows_events.py", line 783, in _poll
    status = _overlapped.GetQueuedCompletionStatus(self._iocp, ms)
KeyboardInterrupt

During handling of the above exception, another exception occurred:

Traceback (most recent call last):
  File "C:\Users\salibagi\AppData\Local\Programs\Python\Python39\lib\asyncio\events.py", line 80, in _run
    self._context.run(self._callback, *self._args)
  File "C:\Users\salibagi\AppData\Local\Programs\Python\Python39\lib\asyncio\proactor_events.py", line 162, in _call_connection_lost
    self._sock.shutdown(socket.SHUT_RDWR)
OSError: [WinError 10038] —делана попытка выполнить операцию на объекте, не €вл€ющемс€ сокетом
2022-08-10 09:44:19,148:ERROR:Task exception was never retrieved
future: <Task finished name='Task-4' coro=<handler_client() done, defined at C:\Users\salibagi\PycharmProjects\RemoteAccess\RabbitMQ\server.py:45> exception=AttributeError('__aenter__')>
Traceback (most recent call last):
  File "C:\Users\salibagi\PycharmProjects\RemoteAccess\RabbitMQ\server.py", line 68, in handler_client
    async with open('data.txt', 'a') as f:
AttributeError: __aenter__
2022-08-10 09:44:36,492:ERROR:Exception in callback _ProactorBasePipeTransport._call_connection_lost(None)
handle: <Handle _ProactorBasePipeTransport._call_connection_lost(None)>
Traceback (most recent call last):
  File "C:\Users\salibagi\AppData\Local\Programs\Python\Python39\lib\asyncio\runners.py", line 44, in run
    return loop.run_until_complete(main)
  File "C:\Users\salibagi\AppData\Local\Programs\Python\Python39\lib\asyncio\base_events.py", line 629, in run_until_complete
    self.run_forever()
  File "C:\Users\salibagi\AppData\Local\Programs\Python\Python39\lib\asyncio\windows_events.py", line 316, in run_forever
    super().run_forever()
  File "C:\Users\salibagi\AppData\Local\Programs\Python\Python39\lib\asyncio\base_events.py", line 596, in run_forever
    self._run_once()
  File "C:\Users\salibagi\AppData\Local\Programs\Python\Python39\lib\asyncio\base_events.py", line 1854, in _run_once
    event_list = self._selector.select(timeout)
  File "C:\Users\salibagi\AppData\Local\Programs\Python\Python39\lib\asyncio\windows_events.py", line 434, in select
    self._poll(timeout)
  File "C:\Users\salibagi\AppData\Local\Programs\Python\Python39\lib\asyncio\windows_events.py", line 783, in _poll
    status = _overlapped.GetQueuedCompletionStatus(self._iocp, ms)
KeyboardInterrupt

During handling of the above exception, another exception occurred:

Traceback (most recent call last):
  File "C:\Users\salibagi\AppData\Local\Programs\Python\Python39\lib\asyncio\events.py", line 80, in _run
    self._context.run(self._callback, *self._args)
  File "C:\Users\salibagi\AppData\Local\Programs\Python\Python39\lib\asyncio\proactor_events.py", line 162, in _call_connection_lost
    self._sock.shutdown(socket.SHUT_RDWR)
OSError: [WinError 10038] —делана попытка выполнить операцию на объекте, не €вл€ющемс€ сокетом
2022-08-10 09:44:37,967:ERROR:Task exception was never retrieved
future: <Task finished name='Task-4' coro=<handler_client() done, defined at C:\Users\salibagi\PycharmProjects\RemoteAccess\RabbitMQ\server.py:45> exception=AttributeError('__aenter__')>
Traceback (most recent call last):
  File "C:\Users\salibagi\PycharmProjects\RemoteAccess\RabbitMQ\server.py", line 68, in handler_client
    async with open('data.txt', 'a') as f:
AttributeError: __aenter__
2022-08-10 09:44:45,965:ERROR:Exception in callback _ProactorBasePipeTransport._call_connection_lost(None)
handle: <Handle _ProactorBasePipeTransport._call_connection_lost(None)>
Traceback (most recent call last):
  File "C:\Users\salibagi\AppData\Local\Programs\Python\Python39\lib\asyncio\runners.py", line 44, in run
    return loop.run_until_complete(main)
  File "C:\Users\salibagi\AppData\Local\Programs\Python\Python39\lib\asyncio\base_events.py", line 629, in run_until_complete
    self.run_forever()
  File "C:\Users\salibagi\AppData\Local\Programs\Python\Python39\lib\asyncio\windows_events.py", line 316, in run_forever
    super().run_forever()
  File "C:\Users\salibagi\AppData\Local\Programs\Python\Python39\lib\asyncio\base_events.py", line 596, in run_forever
    self._run_once()
  File "C:\Users\salibagi\AppData\Local\Programs\Python\Python39\lib\asyncio\base_events.py", line 1854, in _run_once
    event_list = self._selector.select(timeout)
  File "C:\Users\salibagi\AppData\Local\Programs\Python\Python39\lib\asyncio\windows_events.py", line 434, in select
    self._poll(timeout)
  File "C:\Users\salibagi\AppData\Local\Programs\Python\Python39\lib\asyncio\windows_events.py", line 783, in _poll
    status = _overlapped.GetQueuedCompletionStatus(self._iocp, ms)
KeyboardInterrupt

During handling of the above exception, another exception occurred:

Traceback (most recent call last):
  File "C:\Users\salibagi\AppData\Local\Programs\Python\Python39\lib\asyncio\events.py", line 80, in _run
    self._context.run(self._callback, *self._args)
  File "C:\Users\salibagi\AppData\Local\Programs\Python\Python39\lib\asyncio\proactor_events.py", line 162, in _call_connection_lost
    self._sock.shutdown(socket.SHUT_RDWR)
OSError: [WinError 10038] —делана попытка выполнить операцию на объекте, не €вл€ющемс€ сокетом
2022-08-10 09:44:47,544:ERROR:Task exception was never retrieved
future: <Task finished name='Task-4' coro=<handler_client() done, defined at C:\Users\salibagi\PycharmProjects\RemoteAccess\RabbitMQ\server.py:45> exception=SyntaxError('unexpected EOF while parsing', ('<string>', 0, 0, ''))>
Traceback (most recent call last):
  File "C:\Users\salibagi\PycharmProjects\RemoteAccess\RabbitMQ\server.py", line 50, in handler_client
    response = str(eval(request))
  File "<string>", line 0
    
SyntaxError: unexpected EOF while parsing
2022-08-10 09:45:04,014:ERROR:Exception in callback _ProactorBasePipeTransport._call_connection_lost(None)
handle: <Handle _ProactorBasePipeTransport._call_connection_lost(None)>
Traceback (most recent call last):
  File "C:\Users\salibagi\AppData\Local\Programs\Python\Python39\lib\asyncio\runners.py", line 44, in run
    return loop.run_until_complete(main)
  File "C:\Users\salibagi\AppData\Local\Programs\Python\Python39\lib\asyncio\base_events.py", line 629, in run_until_complete
    self.run_forever()
  File "C:\Users\salibagi\AppData\Local\Programs\Python\Python39\lib\asyncio\windows_events.py", line 316, in run_forever
    super().run_forever()
  File "C:\Users\salibagi\AppData\Local\Programs\Python\Python39\lib\asyncio\base_events.py", line 596, in run_forever
    self._run_once()
  File "C:\Users\salibagi\AppData\Local\Programs\Python\Python39\lib\asyncio\base_events.py", line 1854, in _run_once
    event_list = self._selector.select(timeout)
  File "C:\Users\salibagi\AppData\Local\Programs\Python\Python39\lib\asyncio\windows_events.py", line 434, in select
    self._poll(timeout)
  File "C:\Users\salibagi\AppData\Local\Programs\Python\Python39\lib\asyncio\windows_events.py", line 783, in _poll
    status = _overlapped.GetQueuedCompletionStatus(self._iocp, ms)
KeyboardInterrupt

During handling of the above exception, another exception occurred:

Traceback (most recent call last):
  File "C:\Users\salibagi\AppData\Local\Programs\Python\Python39\lib\asyncio\events.py", line 80, in _run
    self._context.run(self._callback, *self._args)
  File "C:\Users\salibagi\AppData\Local\Programs\Python\Python39\lib\asyncio\proactor_events.py", line 162, in _call_connection_lost
    self._sock.shutdown(socket.SHUT_RDWR)
OSError: [WinError 10038] —делана попытка выполнить операцию на объекте, не €вл€ющемс€ сокетом
2022-08-10 10:58:30,929:ERROR:Task exception was never retrieved
future: <Task finished name='Task-4' coro=<handler_client() done, defined at C:\Users\salibagi\PycharmProjects\RemoteAccess\RabbitMQ\server.py:46> exception=SyntaxError('unexpected EOF while parsing', ('<string>', 0, 0, ''))>
Traceback (most recent call last):
  File "C:\Users\salibagi\PycharmProjects\RemoteAccess\RabbitMQ\server.py", line 51, in handler_client
    response = str(eval(request))
  File "<string>", line 0
    
SyntaxError: unexpected EOF while parsing
2022-08-10 10:58:42,862:ERROR:Task exception was never retrieved
future: <Task finished name='Task-6' coro=<handler_client() done, defined at C:\Users\salibagi\PycharmProjects\RemoteAccess\RabbitMQ\server.py:46> exception=SyntaxError('unexpected EOF while parsing', ('<string>', 0, 0, ''))>
Traceback (most recent call last):
  File "C:\Users\salibagi\PycharmProjects\RemoteAccess\RabbitMQ\server.py", line 51, in handler_client
    response = str(eval(request))
  File "<string>", line 0
    
SyntaxError: unexpected EOF while parsing
2022-08-10 11:00:07,357:ERROR:Task exception was never retrieved
future: <Task finished name='Task-4' coro=<handler_client() done, defined at C:\Users\salibagi\PycharmProjects\RemoteAccess\RabbitMQ\server.py:46> exception=SyntaxError('unexpected EOF while parsing', ('<string>', 0, 0, ''))>
Traceback (most recent call last):
  File "C:\Users\salibagi\PycharmProjects\RemoteAccess\RabbitMQ\server.py", line 51, in handler_client
    response = str(eval(request))
  File "<string>", line 0
    
SyntaxError: unexpected EOF while parsing
